#include <iostream>
#include <stdexcept>

using namespace std;

double razdel(double a, double b) 
{
    if (b == 0) 
    {
        throw runtime_error("Ошибка: Деление на ноль");
    }
    return a / b;
}

int main() 
{
    double num1, num2;

    try 
    {
        cout << "Введите первое число: ";
        cin >> numberone;

        if (cin.fail()) 
        {
            throw invalid_argument("Некорректные данные");
        }

        cout << "Введите второе число: ";
        cin >> num2;

        if (cin.fail()) 
        {
            throw invalid_argument("Некорректные данные");
        }

        double result = razdel(num1, num2);
        cout << "Результат деления: " << result << endl;

    } catch (const runtime_error& e) 
    {
        cout << e.what() << endl;
    } catch (const invalid_argument& e) 
    {
        cout << e.what() << endl;
    } catch (const exception& e) 
    {
        cout << "Произошла неожиданная ошибка: " << e.what() << endl;
    }
}
